package com.joshj5hawk.worldgen.structures;

import java.util.Random;

import net.minecraft.block.Block;
import net.minecraft.block.material.Material;
import net.minecraft.init.Blocks;
import net.minecraft.world.World;
import net.minecraft.world.gen.feature.WorldGenerator;

public class StructureSmallHouse extends WorldGenerator
{
	protected Block[] GetValidSpawnBlocks()
	{
		return new Block[]
		{
			Blocks.grass,
			Blocks.stone,
			Blocks.sand,
			Blocks.dirt,
		};
	}

	public boolean LocationIsValidSpawn(World world, int x, int y, int z)
	{
		int distanceToAir = 0;
		Block checkBlock = world.getBlock(x, y, z);

		while (checkBlock != Blocks.air)
		{
			distanceToAir++;
			checkBlock = world.getBlock(x, y + distanceToAir, z);
		}

		if (distanceToAir > 1)
		{
			return false;
		}

		y += distanceToAir - 1;

		Block block = world.getBlock(x, y, z);
		Block blockAbove = world.getBlock(x, y + 1, z);
		Block blockBelow = world.getBlock(x, y - 1, z);

		for (Block i : GetValidSpawnBlocks())
		{
			if (blockAbove != Blocks.air)
			{
				return false;
			}
			if (block == i)
			{
				return true;
			}
			else if (block == Blocks.snow_layer && blockBelow == i)
			{
				return true;
			}
			else if (block.getMaterial() == Material.plants && blockBelow == i)
			{
				return true;
			}
		}
		return false;
	}

	public boolean generate(World world, Random rand, int x, int y, int z)
	{
		int i = rand.nextInt(1);

		if(i == 0)
		{
		    generate_r0(world, rand, x, y, z);
		}

       return true;

	}

	public boolean generate_r0(World world, Random rand, int x, int y, int z)
	{
		if(!LocationIsValidSpawn(world, x, y, z) || !LocationIsValidSpawn(world, x + 8, y, z) || !LocationIsValidSpawn(world, x + 8, y, z + 9) || !LocationIsValidSpawn(world, x, y, z + 9))
		{
			return false;
		}

		world.setBlock(x + 0, y + 0, z + 0, Blocks.dirt, 0, 3);
		world.setBlock(x + 1, y + 0, z + 0, Blocks.dirt, 0, 3);
		world.setBlock(x + 2, y + 0, z + 0, Blocks.dirt, 0, 3);
		world.setBlock(x + 3, y + 0, z + 0, Blocks.dirt, 0, 3);
		world.setBlock(x + 4, y + 0, z + 0, Blocks.dirt, 0, 3);
		world.setBlock(x + 5, y + 0, z + 0, Blocks.dirt, 0, 3);
		world.setBlock(x + 6, y + 0, z + 0, Blocks.dirt, 0, 3);
		world.setBlock(x + 7, y + 0, z + 0, Blocks.dirt, 0, 3);
		world.setBlock(x + 8, y + 0, z + 0, Blocks.dirt, 0, 3);
		world.setBlock(x + 0, y + 0, z + 1, Blocks.dirt, 0, 3);
		world.setBlock(x + 1, y + 0, z + 1, Blocks.dirt, 0, 3);
		world.setBlock(x + 2, y + 0, z + 1, Blocks.dirt, 0, 3);
		world.setBlock(x + 3, y + 0, z + 1, Blocks.dirt, 0, 3);
		world.setBlock(x + 4, y + 0, z + 1, Blocks.dirt, 0, 3);
		world.setBlock(x + 5, y + 0, z + 1, Blocks.dirt, 0, 3);
		world.setBlock(x + 6, y + 0, z + 1, Blocks.dirt, 0, 3);
		world.setBlock(x + 7, y + 0, z + 1, Blocks.dirt, 0, 3);
		world.setBlock(x + 8, y + 0, z + 1, Blocks.dirt, 0, 3);
		world.setBlock(x + 0, y + 0, z + 2, Blocks.dirt, 0, 3);
		world.setBlock(x + 1, y + 0, z + 2, Blocks.dirt, 0, 3);
		world.setBlock(x + 2, y + 0, z + 2, Blocks.dirt, 0, 3);
		world.setBlock(x + 3, y + 0, z + 2, Blocks.dirt, 0, 3);
		world.setBlock(x + 4, y + 0, z + 2, Blocks.dirt, 0, 3);
		world.setBlock(x + 5, y + 0, z + 2, Blocks.dirt, 0, 3);
		world.setBlock(x + 6, y + 0, z + 2, Blocks.dirt, 0, 3);
		world.setBlock(x + 7, y + 0, z + 2, Blocks.grass, 0, 3);
		world.setBlock(x + 8, y + 0, z + 2, Blocks.dirt, 0, 3);
		world.setBlock(x + 0, y + 0, z + 3, Blocks.dirt, 0, 3);
		world.setBlock(x + 1, y + 0, z + 3, Blocks.dirt, 0, 3);
		world.setBlock(x + 2, y + 0, z + 3, Blocks.dirt, 0, 3);
		world.setBlock(x + 3, y + 0, z + 3, Blocks.dirt, 0, 3);
		world.setBlock(x + 4, y + 0, z + 3, Blocks.dirt, 0, 3);
		world.setBlock(x + 5, y + 0, z + 3, Blocks.dirt, 0, 3);
		world.setBlock(x + 6, y + 0, z + 3, Blocks.dirt, 0, 3);
		world.setBlock(x + 7, y + 0, z + 3, Blocks.dirt, 0, 3);
		world.setBlock(x + 8, y + 0, z + 3, Blocks.dirt, 0, 3);
		world.setBlock(x + 0, y + 0, z + 4, Blocks.dirt, 0, 3);
		world.setBlock(x + 1, y + 0, z + 4, Blocks.dirt, 0, 3);
		world.setBlock(x + 2, y + 0, z + 4, Blocks.dirt, 0, 3);
		world.setBlock(x + 3, y + 0, z + 4, Blocks.dirt, 0, 3);
		world.setBlock(x + 4, y + 0, z + 4, Blocks.dirt, 0, 3);
		world.setBlock(x + 5, y + 0, z + 4, Blocks.dirt, 0, 3);
		world.setBlock(x + 6, y + 0, z + 4, Blocks.dirt, 0, 3);
		world.setBlock(x + 7, y + 0, z + 4, Blocks.dirt, 0, 3);
		world.setBlock(x + 8, y + 0, z + 4, Blocks.dirt, 0, 3);
		world.setBlock(x + 0, y + 0, z + 5, Blocks.dirt, 0, 3);
		world.setBlock(x + 1, y + 0, z + 5, Blocks.redstone_block, 0, 3);
		world.setBlock(x + 2, y + 0, z + 5, Blocks.dirt, 0, 3);
		world.setBlock(x + 3, y + 0, z + 5, Blocks.dirt, 0, 3);
		world.setBlock(x + 4, y + 0, z + 5, Blocks.dirt, 0, 3);
		world.setBlock(x + 5, y + 0, z + 5, Blocks.dirt, 0, 3);
		world.setBlock(x + 6, y + 0, z + 5, Blocks.dirt, 0, 3);
		world.setBlock(x + 7, y + 0, z + 5, Blocks.redstone_block, 0, 3);
		world.setBlock(x + 8, y + 0, z + 5, Blocks.dirt, 0, 3);
		world.setBlock(x + 0, y + 0, z + 6, Blocks.dirt, 0, 3);
		world.setBlock(x + 1, y + 0, z + 6, Blocks.dirt, 0, 3);
		world.setBlock(x + 2, y + 0, z + 6, Blocks.dirt, 0, 3);
		world.setBlock(x + 3, y + 0, z + 6, Blocks.dirt, 0, 3);
		world.setBlock(x + 4, y + 0, z + 6, Blocks.dirt, 0, 3);
		world.setBlock(x + 5, y + 0, z + 6, Blocks.dirt, 0, 3);
		world.setBlock(x + 6, y + 0, z + 6, Blocks.dirt, 0, 3);
		world.setBlock(x + 7, y + 0, z + 6, Blocks.dirt, 0, 3);
		world.setBlock(x + 8, y + 0, z + 6, Blocks.dirt, 0, 3);
		world.setBlock(x + 0, y + 0, z + 7, Blocks.dirt, 0, 3);
		world.setBlock(x + 1, y + 0, z + 7, Blocks.dirt, 0, 3);
		world.setBlock(x + 2, y + 0, z + 7, Blocks.dirt, 0, 3);
		world.setBlock(x + 3, y + 0, z + 7, Blocks.dirt, 0, 3);
		world.setBlock(x + 4, y + 0, z + 7, Blocks.dirt, 0, 3);
		world.setBlock(x + 5, y + 0, z + 7, Blocks.dirt, 0, 3);
		world.setBlock(x + 6, y + 0, z + 7, Blocks.dirt, 0, 3);
		world.setBlock(x + 7, y + 0, z + 7, Blocks.dirt, 0, 3);
		world.setBlock(x + 8, y + 0, z + 7, Blocks.dirt, 0, 3);
		world.setBlock(x + 0, y + 0, z + 8, Blocks.dirt, 0, 3);
		world.setBlock(x + 1, y + 0, z + 8, Blocks.redstone_block, 0, 3);
		world.setBlock(x + 2, y + 0, z + 8, Blocks.dirt, 0, 3);
		world.setBlock(x + 3, y + 0, z + 8, Blocks.dirt, 0, 3);
		world.setBlock(x + 4, y + 0, z + 8, Blocks.dirt, 0, 3);
		world.setBlock(x + 5, y + 0, z + 8, Blocks.dirt, 0, 3);
		world.setBlock(x + 6, y + 0, z + 8, Blocks.dirt, 0, 3);
		world.setBlock(x + 7, y + 0, z + 8, Blocks.redstone_block, 0, 3);
		world.setBlock(x + 8, y + 0, z + 8, Blocks.dirt, 0, 3);
		world.setBlock(x + 0, y + 0, z + 9, Blocks.dirt, 0, 3);
		world.setBlock(x + 1, y + 0, z + 9, Blocks.dirt, 0, 3);
		world.setBlock(x + 2, y + 0, z + 9, Blocks.dirt, 0, 3);
		world.setBlock(x + 3, y + 0, z + 9, Blocks.dirt, 0, 3);
		world.setBlock(x + 4, y + 0, z + 9, Blocks.dirt, 0, 3);
		world.setBlock(x + 5, y + 0, z + 9, Blocks.dirt, 0, 3);
		world.setBlock(x + 6, y + 0, z + 9, Blocks.dirt, 0, 3);
		world.setBlock(x + 7, y + 0, z + 9, Blocks.dirt, 0, 3);
		world.setBlock(x + 8, y + 0, z + 9, Blocks.dirt, 0, 3);
		world.setBlock(x + 0, y + 1, z + 0, Blocks.grass, 0, 3);
		world.setBlock(x + 1, y + 1, z + 0, Blocks.grass, 0, 3);
		world.setBlock(x + 2, y + 1, z + 0, Blocks.grass, 0, 3);
		world.setBlock(x + 3, y + 1, z + 0, Blocks.grass, 0, 3);
		world.setBlock(x + 4, y + 1, z + 0, Blocks.grass, 0, 3);
		world.setBlock(x + 5, y + 1, z + 0, Blocks.grass, 0, 3);
		world.setBlock(x + 6, y + 1, z + 0, Blocks.grass, 0, 3);
		world.setBlock(x + 7, y + 1, z + 0, Blocks.grass, 0, 3);
		world.setBlock(x + 8, y + 1, z + 0, Blocks.grass, 0, 3);
		world.setBlock(x + 0, y + 1, z + 1, Blocks.grass, 0, 3);
		world.setBlock(x + 1, y + 1, z + 1, Blocks.farmland, 7, 3);
		world.setBlock(x + 2, y + 1, z + 1, Blocks.water, 0, 3);
		world.setBlock(x + 3, y + 1, z + 1, Blocks.farmland, 7, 3);
		world.setBlock(x + 4, y + 1, z + 1, Blocks.grass, 0, 3);
		world.setBlock(x + 5, y + 1, z + 1, Blocks.farmland, 7, 3);
		world.setBlock(x + 6, y + 1, z + 1, Blocks.water, 0, 3);
		world.setBlock(x + 7, y + 1, z + 1, Blocks.farmland, 7, 3);
		world.setBlock(x + 8, y + 1, z + 1, Blocks.grass, 0, 3);
		world.setBlock(x + 0, y + 1, z + 2, Blocks.grass, 0, 3);
		world.setBlock(x + 1, y + 1, z + 2, Blocks.farmland, 7, 3);
		world.setBlock(x + 2, y + 1, z + 2, Blocks.water, 0, 3);
		world.setBlock(x + 3, y + 1, z + 2, Blocks.farmland, 7, 3);
		world.setBlock(x + 4, y + 1, z + 2, Blocks.grass, 0, 3);
		world.setBlock(x + 5, y + 1, z + 2, Blocks.farmland, 7, 3);
		world.setBlock(x + 6, y + 1, z + 2, Blocks.water, 0, 3);
		world.setBlock(x + 7, y + 1, z + 2, Blocks.farmland, 7, 3);
		world.setBlock(x + 8, y + 1, z + 2, Blocks.grass, 0, 3);
		world.setBlock(x + 0, y + 1, z + 3, Blocks.grass, 0, 3);
		world.setBlock(x + 1, y + 1, z + 3, Blocks.farmland, 7, 3);
		world.setBlock(x + 2, y + 1, z + 3, Blocks.water, 0, 3);
		world.setBlock(x + 3, y + 1, z + 3, Blocks.farmland, 7, 3);
		world.setBlock(x + 4, y + 1, z + 3, Blocks.grass, 0, 3);
		world.setBlock(x + 5, y + 1, z + 3, Blocks.farmland, 7, 3);
		world.setBlock(x + 6, y + 1, z + 3, Blocks.water, 0, 3);
		world.setBlock(x + 7, y + 1, z + 3, Blocks.farmland, 7, 3);
		world.setBlock(x + 8, y + 1, z + 3, Blocks.grass, 0, 3);
		world.setBlock(x + 0, y + 1, z + 4, Blocks.dirt, 0, 3);
		world.setBlock(x + 1, y + 1, z + 4, Blocks.dirt, 0, 3);
		world.setBlock(x + 2, y + 1, z + 4, Blocks.dirt, 0, 3);
		world.setBlock(x + 3, y + 1, z + 4, Blocks.dirt, 0, 3);
		world.setBlock(x + 4, y + 1, z + 4, Blocks.stonebrick, 0, 3);
		world.setBlock(x + 5, y + 1, z + 4, Blocks.dirt, 0, 3);
		world.setBlock(x + 6, y + 1, z + 4, Blocks.dirt, 0, 3);
		world.setBlock(x + 7, y + 1, z + 4, Blocks.dirt, 0, 3);
		world.setBlock(x + 8, y + 1, z + 4, Blocks.dirt, 0, 3);
		world.setBlock(x + 0, y + 1, z + 5, Blocks.dirt, 0, 3);
		world.setBlock(x + 1, y + 1, z + 5, Blocks.lit_redstone_lamp, 0, 3);
		world.setBlock(x + 2, y + 1, z + 5, Blocks.stonebrick, 0, 3);
		world.setBlock(x + 3, y + 1, z + 5, Blocks.stonebrick, 0, 3);
		world.setBlock(x + 4, y + 1, z + 5, Blocks.stonebrick, 0, 3);
		world.setBlock(x + 5, y + 1, z + 5, Blocks.stonebrick, 0, 3);
		world.setBlock(x + 6, y + 1, z + 5, Blocks.stonebrick, 0, 3);
		world.setBlock(x + 7, y + 1, z + 5, Blocks.lit_redstone_lamp, 0, 3);
		world.setBlock(x + 8, y + 1, z + 5, Blocks.dirt, 0, 3);
		world.setBlock(x + 0, y + 1, z + 6, Blocks.dirt, 0, 3);
		world.setBlock(x + 1, y + 1, z + 6, Blocks.stonebrick, 0, 3);
		world.setBlock(x + 2, y + 1, z + 6, Blocks.stonebrick, 0, 3);
		world.setBlock(x + 3, y + 1, z + 6, Blocks.stonebrick, 0, 3);
		world.setBlock(x + 4, y + 1, z + 6, Blocks.stonebrick, 3, 3);
		world.setBlock(x + 5, y + 1, z + 6, Blocks.stonebrick, 0, 3);
		world.setBlock(x + 6, y + 1, z + 6, Blocks.stonebrick, 0, 3);
		world.setBlock(x + 7, y + 1, z + 6, Blocks.stonebrick, 0, 3);
		world.setBlock(x + 8, y + 1, z + 6, Blocks.dirt, 0, 3);
		world.setBlock(x + 0, y + 1, z + 7, Blocks.dirt, 0, 3);
		world.setBlock(x + 1, y + 1, z + 7, Blocks.stonebrick, 0, 3);
		world.setBlock(x + 2, y + 1, z + 7, Blocks.stonebrick, 0, 3);
		world.setBlock(x + 3, y + 1, z + 7, Blocks.stonebrick, 0, 3);
		world.setBlock(x + 4, y + 1, z + 7, Blocks.stonebrick, 3, 3);
		world.setBlock(x + 5, y + 1, z + 7, Blocks.stonebrick, 0, 3);
		world.setBlock(x + 6, y + 1, z + 7, Blocks.stonebrick, 0, 3);
		world.setBlock(x + 7, y + 1, z + 7, Blocks.stonebrick, 0, 3);
		world.setBlock(x + 8, y + 1, z + 7, Blocks.dirt, 0, 3);
		world.setBlock(x + 0, y + 1, z + 8, Blocks.dirt, 0, 3);
		world.setBlock(x + 1, y + 1, z + 8, Blocks.lit_redstone_lamp, 0, 3);
		world.setBlock(x + 2, y + 1, z + 8, Blocks.stonebrick, 0, 3);
		world.setBlock(x + 3, y + 1, z + 8, Blocks.stonebrick, 0, 3);
		world.setBlock(x + 4, y + 1, z + 8, Blocks.stonebrick, 0, 3);
		world.setBlock(x + 5, y + 1, z + 8, Blocks.stonebrick, 0, 3);
		world.setBlock(x + 6, y + 1, z + 8, Blocks.stonebrick, 0, 3);
		world.setBlock(x + 7, y + 1, z + 8, Blocks.lit_redstone_lamp, 0, 3);
		world.setBlock(x + 8, y + 1, z + 8, Blocks.dirt, 0, 3);
		world.setBlock(x + 0, y + 1, z + 9, Blocks.dirt, 0, 3);
		world.setBlock(x + 1, y + 1, z + 9, Blocks.dirt, 0, 3);
		world.setBlock(x + 2, y + 1, z + 9, Blocks.dirt, 0, 3);
		world.setBlock(x + 3, y + 1, z + 9, Blocks.dirt, 0, 3);
		world.setBlock(x + 4, y + 1, z + 9, Blocks.dirt, 0, 3);
		world.setBlock(x + 5, y + 1, z + 9, Blocks.dirt, 0, 3);
		world.setBlock(x + 6, y + 1, z + 9, Blocks.dirt, 0, 3);
		world.setBlock(x + 7, y + 1, z + 9, Blocks.dirt, 0, 3);
		world.setBlock(x + 8, y + 1, z + 9, Blocks.dirt, 0, 3);
		world.setBlock(x + 0, y + 2, z + 0, Blocks.cobblestone_wall, 1, 3);
		world.setBlock(x + 1, y + 2, z + 0, Blocks.cobblestone_wall, 1, 3);
		world.setBlock(x + 2, y + 2, z + 0, Blocks.cobblestone_wall, 1, 3);
		world.setBlock(x + 3, y + 2, z + 0, Blocks.cobblestone_wall, 1, 3);
		world.setBlock(x + 4, y + 2, z + 0, Blocks.fence_gate, 2, 3);
		world.setBlock(x + 5, y + 2, z + 0, Blocks.cobblestone_wall, 1, 3);
		world.setBlock(x + 6, y + 2, z + 0, Blocks.cobblestone_wall, 1, 3);
		world.setBlock(x + 7, y + 2, z + 0, Blocks.cobblestone_wall, 1, 3);
		world.setBlock(x + 8, y + 2, z + 0, Blocks.cobblestone_wall, 1, 3);
		world.setBlock(x + 0, y + 2, z + 1, Blocks.cobblestone_wall, 1, 3);
		world.setBlock(x + 1, y + 2, z + 1, Blocks.carrots, 7, 3);
		world.setBlock(x + 2, y + 2, z + 1, Blocks.air, 0, 3);
		world.setBlock(x + 3, y + 2, z + 1, Blocks.potatoes, 7, 3);
		world.setBlock(x + 4, y + 2, z + 1, Blocks.air, 0, 3);
		world.setBlock(x + 5, y + 2, z + 1, Blocks.potatoes, 7, 3);
		world.setBlock(x + 6, y + 2, z + 1, Blocks.air, 0, 3);
		world.setBlock(x + 7, y + 2, z + 1, Blocks.carrots, 7, 3);
		world.setBlock(x + 8, y + 2, z + 1, Blocks.cobblestone_wall, 1, 3);
		world.setBlock(x + 0, y + 2, z + 2, Blocks.cobblestone_wall, 1, 3);
		world.setBlock(x + 1, y + 2, z + 2, Blocks.carrots, 7, 3);
		world.setBlock(x + 2, y + 2, z + 2, Blocks.air, 0, 3);
		world.setBlock(x + 3, y + 2, z + 2, Blocks.potatoes, 7, 3);
		world.setBlock(x + 4, y + 2, z + 2, Blocks.air, 0, 3);
		world.setBlock(x + 5, y + 2, z + 2, Blocks.potatoes, 7, 3);
		world.setBlock(x + 6, y + 2, z + 2, Blocks.air, 0, 3);
		world.setBlock(x + 7, y + 2, z + 2, Blocks.carrots, 7, 3);
		world.setBlock(x + 8, y + 2, z + 2, Blocks.cobblestone_wall, 1, 3);
		world.setBlock(x + 0, y + 2, z + 3, Blocks.cobblestone_wall, 1, 3);
		world.setBlock(x + 1, y + 2, z + 3, Blocks.carrots, 7, 3);
		world.setBlock(x + 2, y + 2, z + 3, Blocks.air, 0, 3);
		world.setBlock(x + 3, y + 2, z + 3, Blocks.potatoes, 7, 3);
		world.setBlock(x + 4, y + 2, z + 3, Blocks.air, 0, 3);
		world.setBlock(x + 5, y + 2, z + 3, Blocks.potatoes, 7, 3);
		world.setBlock(x + 6, y + 2, z + 3, Blocks.air, 0, 3);
		world.setBlock(x + 7, y + 2, z + 3, Blocks.carrots, 7, 3);
		world.setBlock(x + 8, y + 2, z + 3, Blocks.cobblestone_wall, 1, 3);
		world.setBlock(x + 0, y + 2, z + 4, Blocks.log, 2, 3);
		world.setBlock(x + 1, y + 2, z + 4, Blocks.log, 6, 3);
		world.setBlock(x + 2, y + 2, z + 4, Blocks.log, 6, 3);
		world.setBlock(x + 3, y + 2, z + 4, Blocks.log, 6, 3);
		world.setBlock(x + 4, y + 2, z + 4, Blocks.wooden_door, 1, 3);
		world.setBlock(x + 5, y + 2, z + 4, Blocks.log, 6, 3);
		world.setBlock(x + 6, y + 2, z + 4, Blocks.log, 6, 3);
		world.setBlock(x + 7, y + 2, z + 4, Blocks.log, 6, 3);
		world.setBlock(x + 8, y + 2, z + 4, Blocks.log, 2, 3);
		world.setBlock(x + 0, y + 2, z + 5, Blocks.log, 10, 3);
		world.setBlock(x + 1, y + 2, z + 5, Blocks.air, 0, 3);
		world.setBlock(x + 2, y + 2, z + 5, Blocks.air, 0, 3);
		world.setBlock(x + 3, y + 2, z + 5, Blocks.air, 0, 3);
		world.setBlock(x + 4, y + 2, z + 5, Blocks.air, 0, 3);
		world.setBlock(x + 5, y + 2, z + 5, Blocks.air, 0, 3);
		world.setBlock(x + 6, y + 2, z + 5, Blocks.air, 0, 3);
		world.setBlock(x + 7, y + 2, z + 5, Blocks.air, 0, 3);
		world.setBlock(x + 8, y + 2, z + 5, Blocks.log, 10, 3);
		world.setBlock(x + 0, y + 2, z + 6, Blocks.log, 10, 3);
		world.setBlock(x + 1, y + 2, z + 6, Blocks.furnace, 5, 3);
		world.setBlock(x + 2, y + 2, z + 6, Blocks.air, 0, 3);
		world.setBlock(x + 3, y + 2, z + 6, Blocks.air, 0, 3);
		world.setBlock(x + 4, y + 2, z + 6, Blocks.air, 0, 3);
		world.setBlock(x + 5, y + 2, z + 6, Blocks.air, 0, 3);
		world.setBlock(x + 6, y + 2, z + 6, Blocks.air, 0, 3);
		world.setBlock(x + 7, y + 2, z + 6, Blocks.chest, 4, 3);
		world.setBlock(x + 8, y + 2, z + 6, Blocks.log, 10, 3);
		world.setBlock(x + 0, y + 2, z + 7, Blocks.log, 10, 3);
		world.setBlock(x + 1, y + 2, z + 7, Blocks.crafting_table, 0, 3);
		world.setBlock(x + 2, y + 2, z + 7, Blocks.air, 0, 3);
		world.setBlock(x + 3, y + 2, z + 7, Blocks.air, 0, 3);
		world.setBlock(x + 4, y + 2, z + 7, Blocks.air, 0, 3);
		world.setBlock(x + 5, y + 2, z + 7, Blocks.air, 0, 3);
		world.setBlock(x + 6, y + 2, z + 7, Blocks.air, 0, 3);
		world.setBlock(x + 7, y + 2, z + 7, Blocks.chest, 4, 3);
		world.setBlock(x + 8, y + 2, z + 7, Blocks.log, 10, 3);
		world.setBlock(x + 0, y + 2, z + 8, Blocks.log, 10, 3);
		world.setBlock(x + 1, y + 2, z + 8, Blocks.air, 0, 3);
		world.setBlock(x + 2, y + 2, z + 8, Blocks.air, 0, 3);
		world.setBlock(x + 3, y + 2, z + 8, Blocks.air, 0, 3);
		world.setBlock(x + 4, y + 2, z + 8, Blocks.air, 0, 3);
		world.setBlock(x + 5, y + 2, z + 8, Blocks.air, 0, 3);
		world.setBlock(x + 6, y + 2, z + 8, Blocks.air, 0, 3);
		world.setBlock(x + 7, y + 2, z + 8, Blocks.air, 0, 3);
		world.setBlock(x + 8, y + 2, z + 8, Blocks.log, 10, 3);
		world.setBlock(x + 0, y + 2, z + 9, Blocks.log, 2, 3);
		world.setBlock(x + 1, y + 2, z + 9, Blocks.log, 6, 3);
		world.setBlock(x + 2, y + 2, z + 9, Blocks.log, 6, 3);
		world.setBlock(x + 3, y + 2, z + 9, Blocks.log, 6, 3);
		world.setBlock(x + 4, y + 2, z + 9, Blocks.log, 6, 3);
		world.setBlock(x + 5, y + 2, z + 9, Blocks.log, 6, 3);
		world.setBlock(x + 6, y + 2, z + 9, Blocks.log, 6, 3);
		world.setBlock(x + 7, y + 2, z + 9, Blocks.log, 6, 3);
		world.setBlock(x + 8, y + 2, z + 9, Blocks.log, 2, 3);
		world.setBlock(x + 0, y + 3, z + 0, Blocks.air, 0, 3);
		world.setBlock(x + 1, y + 3, z + 0, Blocks.air, 0, 3);
		world.setBlock(x + 2, y + 3, z + 0, Blocks.air, 0, 3);
		world.setBlock(x + 3, y + 3, z + 0, Blocks.air, 0, 3);
		world.setBlock(x + 4, y + 3, z + 0, Blocks.air, 0, 3);
		world.setBlock(x + 5, y + 3, z + 0, Blocks.air, 0, 3);
		world.setBlock(x + 6, y + 3, z + 0, Blocks.air, 0, 3);
		world.setBlock(x + 7, y + 3, z + 0, Blocks.air, 0, 3);
		world.setBlock(x + 8, y + 3, z + 0, Blocks.air, 0, 3);
		world.setBlock(x + 0, y + 3, z + 1, Blocks.air, 0, 3);
		world.setBlock(x + 1, y + 3, z + 1, Blocks.air, 0, 3);
		world.setBlock(x + 2, y + 3, z + 1, Blocks.air, 0, 3);
		world.setBlock(x + 3, y + 3, z + 1, Blocks.air, 0, 3);
		world.setBlock(x + 4, y + 3, z + 1, Blocks.air, 0, 3);
		world.setBlock(x + 5, y + 3, z + 1, Blocks.air, 0, 3);
		world.setBlock(x + 6, y + 3, z + 1, Blocks.air, 0, 3);
		world.setBlock(x + 7, y + 3, z + 1, Blocks.air, 0, 3);
		world.setBlock(x + 8, y + 3, z + 1, Blocks.air, 0, 3);
		world.setBlock(x + 0, y + 3, z + 2, Blocks.air, 0, 3);
		world.setBlock(x + 1, y + 3, z + 2, Blocks.air, 0, 3);
		world.setBlock(x + 2, y + 3, z + 2, Blocks.air, 0, 3);
		world.setBlock(x + 3, y + 3, z + 2, Blocks.air, 0, 3);
		world.setBlock(x + 4, y + 3, z + 2, Blocks.air, 0, 3);
		world.setBlock(x + 5, y + 3, z + 2, Blocks.air, 0, 3);
		world.setBlock(x + 6, y + 3, z + 2, Blocks.air, 0, 3);
		world.setBlock(x + 7, y + 3, z + 2, Blocks.air, 0, 3);
		world.setBlock(x + 8, y + 3, z + 2, Blocks.air, 0, 3);
		world.setBlock(x + 0, y + 3, z + 3, Blocks.air, 0, 3);
		world.setBlock(x + 1, y + 3, z + 3, Blocks.air, 0, 3);
		world.setBlock(x + 2, y + 3, z + 3, Blocks.air, 0, 3);
		world.setBlock(x + 3, y + 3, z + 3, Blocks.air, 0, 3);
		world.setBlock(x + 4, y + 3, z + 3, Blocks.air, 0, 3);
		world.setBlock(x + 5, y + 3, z + 3, Blocks.air, 0, 3);
		world.setBlock(x + 6, y + 3, z + 3, Blocks.air, 0, 3);
		world.setBlock(x + 7, y + 3, z + 3, Blocks.air, 0, 3);
		world.setBlock(x + 8, y + 3, z + 3, Blocks.air, 0, 3);
		world.setBlock(x + 0, y + 3, z + 4, Blocks.log, 2, 3);
		world.setBlock(x + 1, y + 3, z + 4, Blocks.glass, 0, 3);
		world.setBlock(x + 2, y + 3, z + 4, Blocks.glass, 0, 3);
		world.setBlock(x + 3, y + 3, z + 4, Blocks.planks, 2, 3);
		world.setBlock(x + 4, y + 3, z + 4, Blocks.wooden_door, 8, 3);
		world.setBlock(x + 5, y + 3, z + 4, Blocks.planks, 2, 3);
		world.setBlock(x + 6, y + 3, z + 4, Blocks.glass, 0, 3);
		world.setBlock(x + 7, y + 3, z + 4, Blocks.glass, 0, 3);
		world.setBlock(x + 8, y + 3, z + 4, Blocks.log, 2, 3);
		world.setBlock(x + 0, y + 3, z + 5, Blocks.planks, 2, 3);
		world.setBlock(x + 1, y + 3, z + 5, Blocks.air, 0, 3);
		world.setBlock(x + 2, y + 3, z + 5, Blocks.air, 0, 3);
		world.setBlock(x + 3, y + 3, z + 5, Blocks.air, 0, 3);
		world.setBlock(x + 4, y + 3, z + 5, Blocks.air, 0, 3);
		world.setBlock(x + 5, y + 3, z + 5, Blocks.air, 0, 3);
		world.setBlock(x + 6, y + 3, z + 5, Blocks.air, 0, 3);
		world.setBlock(x + 7, y + 3, z + 5, Blocks.air, 0, 3);
		world.setBlock(x + 8, y + 3, z + 5, Blocks.planks, 2, 3);
		world.setBlock(x + 0, y + 3, z + 6, Blocks.glass, 0, 3);
		world.setBlock(x + 1, y + 3, z + 6, Blocks.air, 0, 3);
		world.setBlock(x + 2, y + 3, z + 6, Blocks.air, 0, 3);
		world.setBlock(x + 3, y + 3, z + 6, Blocks.air, 0, 3);
		world.setBlock(x + 4, y + 3, z + 6, Blocks.air, 0, 3);
		world.setBlock(x + 5, y + 3, z + 6, Blocks.air, 0, 3);
		world.setBlock(x + 6, y + 3, z + 6, Blocks.air, 0, 3);
		world.setBlock(x + 7, y + 3, z + 6, Blocks.air, 0, 3);
		world.setBlock(x + 8, y + 3, z + 6, Blocks.glass, 0, 3);
		world.setBlock(x + 0, y + 3, z + 7, Blocks.glass, 0, 3);
		world.setBlock(x + 1, y + 3, z + 7, Blocks.air, 0, 3);
		world.setBlock(x + 2, y + 3, z + 7, Blocks.air, 0, 3);
		world.setBlock(x + 3, y + 3, z + 7, Blocks.air, 0, 3);
		world.setBlock(x + 4, y + 3, z + 7, Blocks.air, 0, 3);
		world.setBlock(x + 5, y + 3, z + 7, Blocks.air, 0, 3);
		world.setBlock(x + 6, y + 3, z + 7, Blocks.air, 0, 3);
		world.setBlock(x + 7, y + 3, z + 7, Blocks.air, 0, 3);
		world.setBlock(x + 8, y + 3, z + 7, Blocks.glass, 0, 3);
		world.setBlock(x + 0, y + 3, z + 8, Blocks.planks, 2, 3);
		world.setBlock(x + 1, y + 3, z + 8, Blocks.air, 0, 3);
		world.setBlock(x + 2, y + 3, z + 8, Blocks.air, 0, 3);
		world.setBlock(x + 3, y + 3, z + 8, Blocks.air, 0, 3);
		world.setBlock(x + 4, y + 3, z + 8, Blocks.air, 0, 3);
		world.setBlock(x + 5, y + 3, z + 8, Blocks.air, 0, 3);
		world.setBlock(x + 6, y + 3, z + 8, Blocks.air, 0, 3);
		world.setBlock(x + 7, y + 3, z + 8, Blocks.air, 0, 3);
		world.setBlock(x + 8, y + 3, z + 8, Blocks.planks, 2, 3);
		world.setBlock(x + 0, y + 3, z + 9, Blocks.log, 2, 3);
		world.setBlock(x + 1, y + 3, z + 9, Blocks.glass, 0, 3);
		world.setBlock(x + 2, y + 3, z + 9, Blocks.glass, 0, 3);
		world.setBlock(x + 3, y + 3, z + 9, Blocks.planks, 2, 3);
		world.setBlock(x + 4, y + 3, z + 9, Blocks.planks, 2, 3);
		world.setBlock(x + 5, y + 3, z + 9, Blocks.planks, 2, 3);
		world.setBlock(x + 6, y + 3, z + 9, Blocks.glass, 0, 3);
		world.setBlock(x + 7, y + 3, z + 9, Blocks.glass, 0, 3);
		world.setBlock(x + 8, y + 3, z + 9, Blocks.log, 2, 3);
		world.setBlock(x + 0, y + 4, z + 0, Blocks.air, 0, 3);
		world.setBlock(x + 1, y + 4, z + 0, Blocks.air, 0, 3);
		world.setBlock(x + 2, y + 4, z + 0, Blocks.air, 0, 3);
		world.setBlock(x + 3, y + 4, z + 0, Blocks.air, 0, 3);
		world.setBlock(x + 4, y + 4, z + 0, Blocks.air, 0, 3);
		world.setBlock(x + 5, y + 4, z + 0, Blocks.air, 0, 3);
		world.setBlock(x + 6, y + 4, z + 0, Blocks.air, 0, 3);
		world.setBlock(x + 7, y + 4, z + 0, Blocks.air, 0, 3);
		world.setBlock(x + 8, y + 4, z + 0, Blocks.air, 0, 3);
		world.setBlock(x + 0, y + 4, z + 1, Blocks.air, 0, 3);
		world.setBlock(x + 1, y + 4, z + 1, Blocks.air, 0, 3);
		world.setBlock(x + 2, y + 4, z + 1, Blocks.air, 0, 3);
		world.setBlock(x + 3, y + 4, z + 1, Blocks.air, 0, 3);
		world.setBlock(x + 4, y + 4, z + 1, Blocks.air, 0, 3);
		world.setBlock(x + 5, y + 4, z + 1, Blocks.air, 0, 3);
		world.setBlock(x + 6, y + 4, z + 1, Blocks.air, 0, 3);
		world.setBlock(x + 7, y + 4, z + 1, Blocks.air, 0, 3);
		world.setBlock(x + 8, y + 4, z + 1, Blocks.air, 0, 3);
		world.setBlock(x + 0, y + 4, z + 2, Blocks.air, 0, 3);
		world.setBlock(x + 1, y + 4, z + 2, Blocks.air, 0, 3);
		world.setBlock(x + 2, y + 4, z + 2, Blocks.air, 0, 3);
		world.setBlock(x + 3, y + 4, z + 2, Blocks.air, 0, 3);
		world.setBlock(x + 4, y + 4, z + 2, Blocks.air, 0, 3);
		world.setBlock(x + 5, y + 4, z + 2, Blocks.air, 0, 3);
		world.setBlock(x + 6, y + 4, z + 2, Blocks.air, 0, 3);
		world.setBlock(x + 7, y + 4, z + 2, Blocks.air, 0, 3);
		world.setBlock(x + 8, y + 4, z + 2, Blocks.air, 0, 3);
		world.setBlock(x + 0, y + 4, z + 3, Blocks.air, 0, 3);
		world.setBlock(x + 1, y + 4, z + 3, Blocks.air, 0, 3);
		world.setBlock(x + 2, y + 4, z + 3, Blocks.air, 0, 3);
		world.setBlock(x + 3, y + 4, z + 3, Blocks.air, 0, 3);
		world.setBlock(x + 4, y + 4, z + 3, Blocks.air, 0, 3);
		world.setBlock(x + 5, y + 4, z + 3, Blocks.air, 0, 3);
		world.setBlock(x + 6, y + 4, z + 3, Blocks.air, 0, 3);
		world.setBlock(x + 7, y + 4, z + 3, Blocks.air, 0, 3);
		world.setBlock(x + 8, y + 4, z + 3, Blocks.air, 0, 3);
		world.setBlock(x + 0, y + 4, z + 4, Blocks.log, 2, 3);
		world.setBlock(x + 1, y + 4, z + 4, Blocks.glass, 0, 3);
		world.setBlock(x + 2, y + 4, z + 4, Blocks.glass, 0, 3);
		world.setBlock(x + 3, y + 4, z + 4, Blocks.glass, 0, 3);
		world.setBlock(x + 4, y + 4, z + 4, Blocks.glass, 0, 3);
		world.setBlock(x + 5, y + 4, z + 4, Blocks.glass, 0, 3);
		world.setBlock(x + 6, y + 4, z + 4, Blocks.glass, 0, 3);
		world.setBlock(x + 7, y + 4, z + 4, Blocks.glass, 0, 3);
		world.setBlock(x + 8, y + 4, z + 4, Blocks.log, 2, 3);
		world.setBlock(x + 0, y + 4, z + 5, Blocks.planks, 2, 3);
		world.setBlock(x + 1, y + 4, z + 5, Blocks.air, 0, 3);
		world.setBlock(x + 2, y + 4, z + 5, Blocks.air, 0, 3);
		world.setBlock(x + 3, y + 4, z + 5, Blocks.air, 0, 3);
		world.setBlock(x + 4, y + 4, z + 5, Blocks.air, 0, 3);
		world.setBlock(x + 5, y + 4, z + 5, Blocks.air, 0, 3);
		world.setBlock(x + 6, y + 4, z + 5, Blocks.air, 0, 3);
		world.setBlock(x + 7, y + 4, z + 5, Blocks.air, 0, 3);
		world.setBlock(x + 8, y + 4, z + 5, Blocks.planks, 2, 3);
		world.setBlock(x + 0, y + 4, z + 6, Blocks.glass, 0, 3);
		world.setBlock(x + 1, y + 4, z + 6, Blocks.air, 0, 3);
		world.setBlock(x + 2, y + 4, z + 6, Blocks.air, 0, 3);
		world.setBlock(x + 3, y + 4, z + 6, Blocks.air, 0, 3);
		world.setBlock(x + 4, y + 4, z + 6, Blocks.air, 0, 3);
		world.setBlock(x + 5, y + 4, z + 6, Blocks.air, 0, 3);
		world.setBlock(x + 6, y + 4, z + 6, Blocks.air, 0, 3);
		world.setBlock(x + 7, y + 4, z + 6, Blocks.air, 0, 3);
		world.setBlock(x + 8, y + 4, z + 6, Blocks.glass, 0, 3);
		world.setBlock(x + 0, y + 4, z + 7, Blocks.glass, 0, 3);
		world.setBlock(x + 1, y + 4, z + 7, Blocks.air, 0, 3);
		world.setBlock(x + 2, y + 4, z + 7, Blocks.air, 0, 3);
		world.setBlock(x + 3, y + 4, z + 7, Blocks.air, 0, 3);
		world.setBlock(x + 4, y + 4, z + 7, Blocks.air, 0, 3);
		world.setBlock(x + 5, y + 4, z + 7, Blocks.air, 0, 3);
		world.setBlock(x + 6, y + 4, z + 7, Blocks.air, 0, 3);
		world.setBlock(x + 7, y + 4, z + 7, Blocks.air, 0, 3);
		world.setBlock(x + 8, y + 4, z + 7, Blocks.glass, 0, 3);
		world.setBlock(x + 0, y + 4, z + 8, Blocks.planks, 2, 3);
		world.setBlock(x + 1, y + 4, z + 8, Blocks.air, 0, 3);
		world.setBlock(x + 2, y + 4, z + 8, Blocks.air, 0, 3);
		world.setBlock(x + 3, y + 4, z + 8, Blocks.air, 0, 3);
		world.setBlock(x + 4, y + 4, z + 8, Blocks.air, 0, 3);
		world.setBlock(x + 5, y + 4, z + 8, Blocks.air, 0, 3);
		world.setBlock(x + 6, y + 4, z + 8, Blocks.air, 0, 3);
		world.setBlock(x + 7, y + 4, z + 8, Blocks.air, 0, 3);
		world.setBlock(x + 8, y + 4, z + 8, Blocks.planks, 2, 3);
		world.setBlock(x + 0, y + 4, z + 9, Blocks.log, 2, 3);
		world.setBlock(x + 1, y + 4, z + 9, Blocks.glass, 0, 3);
		world.setBlock(x + 2, y + 4, z + 9, Blocks.glass, 0, 3);
		world.setBlock(x + 3, y + 4, z + 9, Blocks.glass, 0, 3);
		world.setBlock(x + 4, y + 4, z + 9, Blocks.glass, 0, 3);
		world.setBlock(x + 5, y + 4, z + 9, Blocks.glass, 0, 3);
		world.setBlock(x + 6, y + 4, z + 9, Blocks.glass, 0, 3);
		world.setBlock(x + 7, y + 4, z + 9, Blocks.glass, 0, 3);
		world.setBlock(x + 8, y + 4, z + 9, Blocks.log, 2, 3);
		world.setBlock(x + 0, y + 5, z + 0, Blocks.air, 0, 3);
		world.setBlock(x + 1, y + 5, z + 0, Blocks.air, 0, 3);
		world.setBlock(x + 2, y + 5, z + 0, Blocks.air, 0, 3);
		world.setBlock(x + 3, y + 5, z + 0, Blocks.air, 0, 3);
		world.setBlock(x + 4, y + 5, z + 0, Blocks.air, 0, 3);
		world.setBlock(x + 5, y + 5, z + 0, Blocks.air, 0, 3);
		world.setBlock(x + 6, y + 5, z + 0, Blocks.air, 0, 3);
		world.setBlock(x + 7, y + 5, z + 0, Blocks.air, 0, 3);
		world.setBlock(x + 8, y + 5, z + 0, Blocks.air, 0, 3);
		world.setBlock(x + 0, y + 5, z + 1, Blocks.air, 0, 3);
		world.setBlock(x + 1, y + 5, z + 1, Blocks.air, 0, 3);
		world.setBlock(x + 2, y + 5, z + 1, Blocks.air, 0, 3);
		world.setBlock(x + 3, y + 5, z + 1, Blocks.air, 0, 3);
		world.setBlock(x + 4, y + 5, z + 1, Blocks.air, 0, 3);
		world.setBlock(x + 5, y + 5, z + 1, Blocks.air, 0, 3);
		world.setBlock(x + 6, y + 5, z + 1, Blocks.air, 0, 3);
		world.setBlock(x + 7, y + 5, z + 1, Blocks.air, 0, 3);
		world.setBlock(x + 8, y + 5, z + 1, Blocks.air, 0, 3);
		world.setBlock(x + 0, y + 5, z + 2, Blocks.air, 0, 3);
		world.setBlock(x + 1, y + 5, z + 2, Blocks.air, 0, 3);
		world.setBlock(x + 2, y + 5, z + 2, Blocks.air, 0, 3);
		world.setBlock(x + 3, y + 5, z + 2, Blocks.air, 0, 3);
		world.setBlock(x + 4, y + 5, z + 2, Blocks.air, 0, 3);
		world.setBlock(x + 5, y + 5, z + 2, Blocks.air, 0, 3);
		world.setBlock(x + 6, y + 5, z + 2, Blocks.air, 0, 3);
		world.setBlock(x + 7, y + 5, z + 2, Blocks.air, 0, 3);
		world.setBlock(x + 8, y + 5, z + 2, Blocks.air, 0, 3);
		world.setBlock(x + 0, y + 5, z + 3, Blocks.air, 0, 3);
		world.setBlock(x + 1, y + 5, z + 3, Blocks.air, 0, 3);
		world.setBlock(x + 2, y + 5, z + 3, Blocks.air, 0, 3);
		world.setBlock(x + 3, y + 5, z + 3, Blocks.air, 0, 3);
		world.setBlock(x + 4, y + 5, z + 3, Blocks.air, 0, 3);
		world.setBlock(x + 5, y + 5, z + 3, Blocks.air, 0, 3);
		world.setBlock(x + 6, y + 5, z + 3, Blocks.air, 0, 3);
		world.setBlock(x + 7, y + 5, z + 3, Blocks.air, 0, 3);
		world.setBlock(x + 8, y + 5, z + 3, Blocks.air, 0, 3);
		world.setBlock(x + 0, y + 5, z + 4, Blocks.birch_stairs, 0, 3);
		world.setBlock(x + 1, y + 5, z + 4, Blocks.birch_stairs, 2, 3);
		world.setBlock(x + 2, y + 5, z + 4, Blocks.birch_stairs, 2, 3);
		world.setBlock(x + 3, y + 5, z + 4, Blocks.birch_stairs, 2, 3);
		world.setBlock(x + 4, y + 5, z + 4, Blocks.birch_stairs, 2, 3);
		world.setBlock(x + 5, y + 5, z + 4, Blocks.birch_stairs, 2, 3);
		world.setBlock(x + 6, y + 5, z + 4, Blocks.birch_stairs, 2, 3);
		world.setBlock(x + 7, y + 5, z + 4, Blocks.birch_stairs, 2, 3);
		world.setBlock(x + 8, y + 5, z + 4, Blocks.birch_stairs, 2, 3);
		world.setBlock(x + 0, y + 5, z + 5, Blocks.birch_stairs, 0, 3);
		world.setBlock(x + 1, y + 5, z + 5, Blocks.air, 0, 3);
		world.setBlock(x + 2, y + 5, z + 5, Blocks.air, 0, 3);
		world.setBlock(x + 3, y + 5, z + 5, Blocks.air, 0, 3);
		world.setBlock(x + 4, y + 5, z + 5, Blocks.air, 0, 3);
		world.setBlock(x + 5, y + 5, z + 5, Blocks.air, 0, 3);
		world.setBlock(x + 6, y + 5, z + 5, Blocks.air, 0, 3);
		world.setBlock(x + 7, y + 5, z + 5, Blocks.air, 0, 3);
		world.setBlock(x + 8, y + 5, z + 5, Blocks.birch_stairs, 1, 3);
		world.setBlock(x + 0, y + 5, z + 6, Blocks.birch_stairs, 0, 3);
		world.setBlock(x + 1, y + 5, z + 6, Blocks.air, 0, 3);
		world.setBlock(x + 2, y + 5, z + 6, Blocks.air, 0, 3);
		world.setBlock(x + 3, y + 5, z + 6, Blocks.air, 0, 3);
		world.setBlock(x + 4, y + 5, z + 6, Blocks.air, 0, 3);
		world.setBlock(x + 5, y + 5, z + 6, Blocks.air, 0, 3);
		world.setBlock(x + 6, y + 5, z + 6, Blocks.air, 0, 3);
		world.setBlock(x + 7, y + 5, z + 6, Blocks.air, 0, 3);
		world.setBlock(x + 8, y + 5, z + 6, Blocks.birch_stairs, 1, 3);
		world.setBlock(x + 0, y + 5, z + 7, Blocks.birch_stairs, 0, 3);
		world.setBlock(x + 1, y + 5, z + 7, Blocks.air, 0, 3);
		world.setBlock(x + 2, y + 5, z + 7, Blocks.air, 0, 3);
		world.setBlock(x + 3, y + 5, z + 7, Blocks.air, 0, 3);
		world.setBlock(x + 4, y + 5, z + 7, Blocks.air, 0, 3);
		world.setBlock(x + 5, y + 5, z + 7, Blocks.air, 0, 3);
		world.setBlock(x + 6, y + 5, z + 7, Blocks.air, 0, 3);
		world.setBlock(x + 7, y + 5, z + 7, Blocks.air, 0, 3);
		world.setBlock(x + 8, y + 5, z + 7, Blocks.birch_stairs, 1, 3);
		world.setBlock(x + 0, y + 5, z + 8, Blocks.birch_stairs, 0, 3);
		world.setBlock(x + 1, y + 5, z + 8, Blocks.air, 0, 3);
		world.setBlock(x + 2, y + 5, z + 8, Blocks.air, 0, 3);
		world.setBlock(x + 3, y + 5, z + 8, Blocks.air, 0, 3);
		world.setBlock(x + 4, y + 5, z + 8, Blocks.air, 0, 3);
		world.setBlock(x + 5, y + 5, z + 8, Blocks.air, 0, 3);
		world.setBlock(x + 6, y + 5, z + 8, Blocks.air, 0, 3);
		world.setBlock(x + 7, y + 5, z + 8, Blocks.air, 0, 3);
		world.setBlock(x + 8, y + 5, z + 8, Blocks.birch_stairs, 1, 3);
		world.setBlock(x + 0, y + 5, z + 9, Blocks.birch_stairs, 3, 3);
		world.setBlock(x + 1, y + 5, z + 9, Blocks.birch_stairs, 3, 3);
		world.setBlock(x + 2, y + 5, z + 9, Blocks.birch_stairs, 3, 3);
		world.setBlock(x + 3, y + 5, z + 9, Blocks.birch_stairs, 3, 3);
		world.setBlock(x + 4, y + 5, z + 9, Blocks.birch_stairs, 3, 3);
		world.setBlock(x + 5, y + 5, z + 9, Blocks.birch_stairs, 3, 3);
		world.setBlock(x + 6, y + 5, z + 9, Blocks.birch_stairs, 3, 3);
		world.setBlock(x + 7, y + 5, z + 9, Blocks.birch_stairs, 3, 3);
		world.setBlock(x + 8, y + 5, z + 9, Blocks.birch_stairs, 3, 3);
		world.setBlock(x + 0, y + 6, z + 0, Blocks.air, 0, 3);
		world.setBlock(x + 1, y + 6, z + 0, Blocks.air, 0, 3);
		world.setBlock(x + 2, y + 6, z + 0, Blocks.air, 0, 3);
		world.setBlock(x + 3, y + 6, z + 0, Blocks.air, 0, 3);
		world.setBlock(x + 4, y + 6, z + 0, Blocks.air, 0, 3);
		world.setBlock(x + 5, y + 6, z + 0, Blocks.air, 0, 3);
		world.setBlock(x + 6, y + 6, z + 0, Blocks.air, 0, 3);
		world.setBlock(x + 7, y + 6, z + 0, Blocks.air, 0, 3);
		world.setBlock(x + 8, y + 6, z + 0, Blocks.air, 0, 3);
		world.setBlock(x + 0, y + 6, z + 1, Blocks.air, 0, 3);
		world.setBlock(x + 1, y + 6, z + 1, Blocks.air, 0, 3);
		world.setBlock(x + 2, y + 6, z + 1, Blocks.air, 0, 3);
		world.setBlock(x + 3, y + 6, z + 1, Blocks.air, 0, 3);
		world.setBlock(x + 4, y + 6, z + 1, Blocks.air, 0, 3);
		world.setBlock(x + 5, y + 6, z + 1, Blocks.air, 0, 3);
		world.setBlock(x + 6, y + 6, z + 1, Blocks.air, 0, 3);
		world.setBlock(x + 7, y + 6, z + 1, Blocks.air, 0, 3);
		world.setBlock(x + 8, y + 6, z + 1, Blocks.air, 0, 3);
		world.setBlock(x + 0, y + 6, z + 2, Blocks.air, 0, 3);
		world.setBlock(x + 1, y + 6, z + 2, Blocks.air, 0, 3);
		world.setBlock(x + 2, y + 6, z + 2, Blocks.air, 0, 3);
		world.setBlock(x + 3, y + 6, z + 2, Blocks.air, 0, 3);
		world.setBlock(x + 4, y + 6, z + 2, Blocks.air, 0, 3);
		world.setBlock(x + 5, y + 6, z + 2, Blocks.air, 0, 3);
		world.setBlock(x + 6, y + 6, z + 2, Blocks.air, 0, 3);
		world.setBlock(x + 7, y + 6, z + 2, Blocks.air, 0, 3);
		world.setBlock(x + 8, y + 6, z + 2, Blocks.air, 0, 3);
		world.setBlock(x + 0, y + 6, z + 3, Blocks.air, 0, 3);
		world.setBlock(x + 1, y + 6, z + 3, Blocks.air, 0, 3);
		world.setBlock(x + 2, y + 6, z + 3, Blocks.air, 0, 3);
		world.setBlock(x + 3, y + 6, z + 3, Blocks.air, 0, 3);
		world.setBlock(x + 4, y + 6, z + 3, Blocks.air, 0, 3);
		world.setBlock(x + 5, y + 6, z + 3, Blocks.air, 0, 3);
		world.setBlock(x + 6, y + 6, z + 3, Blocks.air, 0, 3);
		world.setBlock(x + 7, y + 6, z + 3, Blocks.air, 0, 3);
		world.setBlock(x + 8, y + 6, z + 3, Blocks.air, 0, 3);
		world.setBlock(x + 0, y + 6, z + 4, Blocks.air, 0, 3);
		world.setBlock(x + 1, y + 6, z + 4, Blocks.air, 0, 3);
		world.setBlock(x + 2, y + 6, z + 4, Blocks.air, 0, 3);
		world.setBlock(x + 3, y + 6, z + 4, Blocks.air, 0, 3);
		world.setBlock(x + 4, y + 6, z + 4, Blocks.air, 0, 3);
		world.setBlock(x + 5, y + 6, z + 4, Blocks.air, 0, 3);
		world.setBlock(x + 6, y + 6, z + 4, Blocks.air, 0, 3);
		world.setBlock(x + 7, y + 6, z + 4, Blocks.air, 0, 3);
		world.setBlock(x + 8, y + 6, z + 4, Blocks.air, 0, 3);
		world.setBlock(x + 0, y + 6, z + 5, Blocks.air, 0, 3);
		world.setBlock(x + 1, y + 6, z + 5, Blocks.birch_stairs, 0, 3);
		world.setBlock(x + 2, y + 6, z + 5, Blocks.birch_stairs, 2, 3);
		world.setBlock(x + 3, y + 6, z + 5, Blocks.birch_stairs, 2, 3);
		world.setBlock(x + 4, y + 6, z + 5, Blocks.birch_stairs, 2, 3);
		world.setBlock(x + 5, y + 6, z + 5, Blocks.birch_stairs, 2, 3);
		world.setBlock(x + 6, y + 6, z + 5, Blocks.birch_stairs, 2, 3);
		world.setBlock(x + 7, y + 6, z + 5, Blocks.birch_stairs, 1, 3);
		world.setBlock(x + 8, y + 6, z + 5, Blocks.air, 0, 3);
		world.setBlock(x + 0, y + 6, z + 6, Blocks.air, 0, 3);
		world.setBlock(x + 1, y + 6, z + 6, Blocks.birch_stairs, 0, 3);
		world.setBlock(x + 2, y + 6, z + 6, Blocks.air, 0, 3);
		world.setBlock(x + 3, y + 6, z + 6, Blocks.air, 0, 3);
		world.setBlock(x + 4, y + 6, z + 6, Blocks.air, 0, 3);
		world.setBlock(x + 5, y + 6, z + 6, Blocks.air, 0, 3);
		world.setBlock(x + 6, y + 6, z + 6, Blocks.air, 0, 3);
		world.setBlock(x + 7, y + 6, z + 6, Blocks.birch_stairs, 1, 3);
		world.setBlock(x + 8, y + 6, z + 6, Blocks.air, 0, 3);
		world.setBlock(x + 0, y + 6, z + 7, Blocks.air, 0, 3);
		world.setBlock(x + 1, y + 6, z + 7, Blocks.birch_stairs, 0, 3);
		world.setBlock(x + 2, y + 6, z + 7, Blocks.air, 0, 3);
		world.setBlock(x + 3, y + 6, z + 7, Blocks.air, 0, 3);
		world.setBlock(x + 4, y + 6, z + 7, Blocks.air, 0, 3);
		world.setBlock(x + 5, y + 6, z + 7, Blocks.air, 0, 3);
		world.setBlock(x + 6, y + 6, z + 7, Blocks.air, 0, 3);
		world.setBlock(x + 7, y + 6, z + 7, Blocks.birch_stairs, 1, 3);
		world.setBlock(x + 8, y + 6, z + 7, Blocks.air, 0, 3);
		world.setBlock(x + 0, y + 6, z + 8, Blocks.air, 0, 3);
		world.setBlock(x + 1, y + 6, z + 8, Blocks.birch_stairs, 3, 3);
		world.setBlock(x + 2, y + 6, z + 8, Blocks.birch_stairs, 3, 3);
		world.setBlock(x + 3, y + 6, z + 8, Blocks.birch_stairs, 3, 3);
		world.setBlock(x + 4, y + 6, z + 8, Blocks.birch_stairs, 3, 3);
		world.setBlock(x + 5, y + 6, z + 8, Blocks.birch_stairs, 3, 3);
		world.setBlock(x + 6, y + 6, z + 8, Blocks.birch_stairs, 3, 3);
		world.setBlock(x + 7, y + 6, z + 8, Blocks.birch_stairs, 3, 3);
		world.setBlock(x + 8, y + 6, z + 8, Blocks.air, 0, 3);
		world.setBlock(x + 0, y + 6, z + 9, Blocks.air, 0, 3);
		world.setBlock(x + 1, y + 6, z + 9, Blocks.air, 0, 3);
		world.setBlock(x + 2, y + 6, z + 9, Blocks.air, 0, 3);
		world.setBlock(x + 3, y + 6, z + 9, Blocks.air, 0, 3);
		world.setBlock(x + 4, y + 6, z + 9, Blocks.air, 0, 3);
		world.setBlock(x + 5, y + 6, z + 9, Blocks.air, 0, 3);
		world.setBlock(x + 6, y + 6, z + 9, Blocks.air, 0, 3);
		world.setBlock(x + 7, y + 6, z + 9, Blocks.air, 0, 3);
		world.setBlock(x + 8, y + 6, z + 9, Blocks.air, 0, 3);
		world.setBlock(x + 0, y + 7, z + 0, Blocks.air, 0, 3);
		world.setBlock(x + 1, y + 7, z + 0, Blocks.air, 0, 3);
		world.setBlock(x + 2, y + 7, z + 0, Blocks.air, 0, 3);
		world.setBlock(x + 3, y + 7, z + 0, Blocks.air, 0, 3);
		world.setBlock(x + 4, y + 7, z + 0, Blocks.air, 0, 3);
		world.setBlock(x + 5, y + 7, z + 0, Blocks.air, 0, 3);
		world.setBlock(x + 6, y + 7, z + 0, Blocks.air, 0, 3);
		world.setBlock(x + 7, y + 7, z + 0, Blocks.air, 0, 3);
		world.setBlock(x + 8, y + 7, z + 0, Blocks.air, 0, 3);
		world.setBlock(x + 0, y + 7, z + 1, Blocks.air, 0, 3);
		world.setBlock(x + 1, y + 7, z + 1, Blocks.air, 0, 3);
		world.setBlock(x + 2, y + 7, z + 1, Blocks.air, 0, 3);
		world.setBlock(x + 3, y + 7, z + 1, Blocks.air, 0, 3);
		world.setBlock(x + 4, y + 7, z + 1, Blocks.air, 0, 3);
		world.setBlock(x + 5, y + 7, z + 1, Blocks.air, 0, 3);
		world.setBlock(x + 6, y + 7, z + 1, Blocks.air, 0, 3);
		world.setBlock(x + 7, y + 7, z + 1, Blocks.air, 0, 3);
		world.setBlock(x + 8, y + 7, z + 1, Blocks.air, 0, 3);
		world.setBlock(x + 0, y + 7, z + 2, Blocks.air, 0, 3);
		world.setBlock(x + 1, y + 7, z + 2, Blocks.air, 0, 3);
		world.setBlock(x + 2, y + 7, z + 2, Blocks.air, 0, 3);
		world.setBlock(x + 3, y + 7, z + 2, Blocks.air, 0, 3);
		world.setBlock(x + 4, y + 7, z + 2, Blocks.air, 0, 3);
		world.setBlock(x + 5, y + 7, z + 2, Blocks.air, 0, 3);
		world.setBlock(x + 6, y + 7, z + 2, Blocks.air, 0, 3);
		world.setBlock(x + 7, y + 7, z + 2, Blocks.air, 0, 3);
		world.setBlock(x + 8, y + 7, z + 2, Blocks.air, 0, 3);
		world.setBlock(x + 0, y + 7, z + 3, Blocks.air, 0, 3);
		world.setBlock(x + 1, y + 7, z + 3, Blocks.air, 0, 3);
		world.setBlock(x + 2, y + 7, z + 3, Blocks.air, 0, 3);
		world.setBlock(x + 3, y + 7, z + 3, Blocks.air, 0, 3);
		world.setBlock(x + 4, y + 7, z + 3, Blocks.air, 0, 3);
		world.setBlock(x + 5, y + 7, z + 3, Blocks.air, 0, 3);
		world.setBlock(x + 6, y + 7, z + 3, Blocks.air, 0, 3);
		world.setBlock(x + 7, y + 7, z + 3, Blocks.air, 0, 3);
		world.setBlock(x + 8, y + 7, z + 3, Blocks.air, 0, 3);
		world.setBlock(x + 0, y + 7, z + 4, Blocks.air, 0, 3);
		world.setBlock(x + 1, y + 7, z + 4, Blocks.air, 0, 3);
		world.setBlock(x + 2, y + 7, z + 4, Blocks.air, 0, 3);
		world.setBlock(x + 3, y + 7, z + 4, Blocks.air, 0, 3);
		world.setBlock(x + 4, y + 7, z + 4, Blocks.air, 0, 3);
		world.setBlock(x + 5, y + 7, z + 4, Blocks.air, 0, 3);
		world.setBlock(x + 6, y + 7, z + 4, Blocks.air, 0, 3);
		world.setBlock(x + 7, y + 7, z + 4, Blocks.air, 0, 3);
		world.setBlock(x + 8, y + 7, z + 4, Blocks.air, 0, 3);
		world.setBlock(x + 0, y + 7, z + 5, Blocks.air, 0, 3);
		world.setBlock(x + 1, y + 7, z + 5, Blocks.air, 0, 3);
		world.setBlock(x + 2, y + 7, z + 5, Blocks.air, 0, 3);
		world.setBlock(x + 3, y + 7, z + 5, Blocks.air, 0, 3);
		world.setBlock(x + 4, y + 7, z + 5, Blocks.air, 0, 3);
		world.setBlock(x + 5, y + 7, z + 5, Blocks.air, 0, 3);
		world.setBlock(x + 6, y + 7, z + 5, Blocks.air, 0, 3);
		world.setBlock(x + 7, y + 7, z + 5, Blocks.air, 0, 3);
		world.setBlock(x + 8, y + 7, z + 5, Blocks.air, 0, 3);
		world.setBlock(x + 0, y + 7, z + 6, Blocks.air, 0, 3);
		world.setBlock(x + 1, y + 7, z + 6, Blocks.air, 0, 3);
		world.setBlock(x + 2, y + 7, z + 6, Blocks.birch_stairs, 2, 3);
		world.setBlock(x + 3, y + 7, z + 6, Blocks.birch_stairs, 2, 3);
		world.setBlock(x + 4, y + 7, z + 6, Blocks.birch_stairs, 2, 3);
		world.setBlock(x + 5, y + 7, z + 6, Blocks.birch_stairs, 2, 3);
		world.setBlock(x + 6, y + 7, z + 6, Blocks.birch_stairs, 1, 3);
		world.setBlock(x + 7, y + 7, z + 6, Blocks.air, 0, 3);
		world.setBlock(x + 8, y + 7, z + 6, Blocks.air, 0, 3);
		world.setBlock(x + 0, y + 7, z + 7, Blocks.air, 0, 3);
		world.setBlock(x + 1, y + 7, z + 7, Blocks.air, 0, 3);
		world.setBlock(x + 2, y + 7, z + 7, Blocks.birch_stairs, 0, 3);
		world.setBlock(x + 3, y + 7, z + 7, Blocks.birch_stairs, 3, 3);
		world.setBlock(x + 4, y + 7, z + 7, Blocks.birch_stairs, 3, 3);
		world.setBlock(x + 5, y + 7, z + 7, Blocks.birch_stairs, 3, 3);
		world.setBlock(x + 6, y + 7, z + 7, Blocks.birch_stairs, 3, 3);
		world.setBlock(x + 7, y + 7, z + 7, Blocks.air, 0, 3);
		world.setBlock(x + 8, y + 7, z + 7, Blocks.air, 0, 3);
		world.setBlock(x + 0, y + 7, z + 8, Blocks.air, 0, 3);
		world.setBlock(x + 1, y + 7, z + 8, Blocks.air, 0, 3);
		world.setBlock(x + 2, y + 7, z + 8, Blocks.air, 0, 3);
		world.setBlock(x + 3, y + 7, z + 8, Blocks.air, 0, 3);
		world.setBlock(x + 4, y + 7, z + 8, Blocks.air, 0, 3);
		world.setBlock(x + 5, y + 7, z + 8, Blocks.air, 0, 3);
		world.setBlock(x + 6, y + 7, z + 8, Blocks.air, 0, 3);
		world.setBlock(x + 7, y + 7, z + 8, Blocks.air, 0, 3);
		world.setBlock(x + 8, y + 7, z + 8, Blocks.air, 0, 3);
		world.setBlock(x + 0, y + 7, z + 9, Blocks.air, 0, 3);
		world.setBlock(x + 1, y + 7, z + 9, Blocks.air, 0, 3);
		world.setBlock(x + 2, y + 7, z + 9, Blocks.air, 0, 3);
		world.setBlock(x + 3, y + 7, z + 9, Blocks.air, 0, 3);
		world.setBlock(x + 4, y + 7, z + 9, Blocks.air, 0, 3);
		world.setBlock(x + 5, y + 7, z + 9, Blocks.air, 0, 3);
		world.setBlock(x + 6, y + 7, z + 9, Blocks.air, 0, 3);
		world.setBlock(x + 7, y + 7, z + 9, Blocks.air, 0, 3);
		world.setBlock(x + 8, y + 7, z + 9, Blocks.air, 0, 3);
		return true;

	}

}